Workbook

Sheet Resumo
A1: Alimentos mais adquiridos no Brasil x base do Marchewski App
A2: POF 2017-2018 (IBGE) cruzada com a tabela de alimentos do app
A4: COMO ESTE RANKING FOI FEITO
A5: Não existe ranking público de 'mais vendidos' por categoria no Brasil — esse dado é
A6: proprietário (Nielsen, Kantar, ABRAS). O que existe e é oficial: a POF do IBGE, que mede
A7: a aquisição alimentar domiciliar per capita anual em kg/pessoa/ano, produto a produto.
A8: É o dado público mais próximo de 'o que o brasileiro mais compra'.
A10: Fonte: IBGE, POF 2017-2018 — SIDRA tabela 2393, variável 1207, período 2018, Brasil.
A11: https://sidra.ibge.gov.br/tabela/2393
A13: A POF traz 329 linhas de produto. 75 delas são resíduo estatístico ('Outros',
A14: 'não especificado') e não são alimento prescritível — foram excluídas. Sobraram 254.
A16: A POF tem entre 3 e 46 produtos por grupo; nenhum grupo chega a 50. Por isso a planilha
... A24: CONTAGEM
A25: Situação | B25: Qtd de produtos | C25: % do total
A26: Já no app | B26: =COUNTIF(Alimentos!$E$2:$E$255,"Já no app") | C26: =B26/$B$29
A27: Falta subir | B27: =COUNTIF(Alimentos!$E$2:$E$255,"Falta subir") | C27: =B27/$B$29
A28: Sem fonte confiável | B28: =COUNTIF(Alimentos!$E$2:$E$255,"Sem fonte") | C28: =B28/$B$29
A29: TOTAL | B29: =SUM(B26:B28) | C29: =B29/$B$29
A31: POR GRUPO DA POF
A32: Grupo | B32: Produtos | C32: Já no app | D32: Falta subir | E32: kg/pessoa/ano
A33: Bebidas e infusões | B33: =COUNTIF(Alimentos!$A$2:$A$255,$A33) | C33: =COUNTIFS(Alimentos!$A$2:$A$255,$A33,Alimentos!$E$2:$E$255,"Já no app") | D33: =COUNTIFS(Alimentos!$A$2:$A$255,$A33,Alimentos!$E$2:$E$255,"Falta subir") | E33: =SUMIF(Alimentos!$A$2:$A$255,$A33,Alimentos!$D$2:$D$255)
A34: Laticínios | B34: =COUNTIF(Alimentos!$A$2:$A$255,$A34) | C34: =COUNTIFS(Alimentos!$A$2:$A$255,$A34,Alimentos!$E$2:$E$255,"Já no app") | D34: =COUNTIFS(Alimentos!$A$2:$A$255,$A34,Alimentos!$E$2:$E$255,"Falta subir") | E34: =SUMIF(Alimentos!$A$2:$A$255,$A34,Alimentos!$D$2:$D$255)
A35: Cereais e leguminosas | B35: =COUNTIF(Alimentos!$A$2:$A$255,$A35) | C35: =COUNTIFS(Alimentos!$A$2:$A$255,$A35,Alimentos!$E$2:$E$255,"Já no app") | D35: =COUNTIFS(Alimentos!$A$2:$A$255,$A35,Alimentos!$E$2:$E$255,"Falta subir") | E35: =SUMIF(Alimentos!$A$2:$A$255,$A35,Alimentos!$D$2:$D$255)
A36: Frutas | B36: =COUNTIF(Alimentos!$A$2:$A$255,$A36) | C36: =COUNTIFS(Alimentos!$A$2:$A$255,$A36,Alimentos!$E$2:$E$255,"Já no app") | D36: =COUNTIFS(Alimentos!$A$2:$A$255,$A36,Alimentos!$E$2:$E$255,"Falta subir") | E36: =SUMIF(Alimentos!$A$2:$A$255,$A36,Alimentos!$D$2:$D$255)
A37: Hortaliças | B37: =COUNTIF(Alimentos!$A$2:$A$255,$A37) | C37: =COUNTIFS(Alimentos!$A$2:$A$255,$A37,Alimentos!$E$2:$E$255,"Já no app") | D37: =COUNTIFS(Alimentos!$A$2:$A$255,$A37,Alimentos!$E$2:$E$255,"Falta subir") | E37: =SUMIF(Alimentos!$A$2:$A$255,$A37,Alimentos!$D$2:$D$255)
A38: Panificados | B38: =COUNTIF(Alimentos!$A$2:$A$255,$A38) | C38: =COUNTIFS(Alimentos!$A$2:$A$255,$A38,Alimentos!$E$2:$E$255,"Já no app") | D38: =COUNTIFS(Alimentos!$A$2:$A$255,$A38,Alimentos!$E$2:$E$255,"Falta subir") | E38: =SUMIF(Alimentos!$A$2:$A$255,$A38,Alimentos!$D$2:$D$255)
A39: Aves e ovos | B39: =COUNTIF(Alimentos!$A$2:$A$255,$A39) | C39: =COUNTIFS(Alimentos!$A$2:$A$255,$A39,Alimentos!$E$2:$E$255,"Já no app") | D39: =COUNTIFS(Alimentos!$A$2:$A$255,$A39,Alimentos!$E$2:$E$255,"Falta subir") | E39: =SUMIF(Alimentos!$A$2:$A$255,$A39,Alimentos!$D$2:$D$255)
A40: Carnes | B40: =COUNTIF(Alimentos!$A$2:$A$255,$A40) | C40: =COUNTIFS(Alimentos!$A$2:$A$255,$A40,Alimentos!$E$2:$E$255,"Já no app") | D40: =COUNTIFS(Alimentos!$A$2:$A$255,$A40,Alimentos!$E$2:$E$255,"Falta subir") | E40: =SUMIF(Alimentos!$A$2:$A$255,$A40,Alimentos!$D$2:$D$255)
A41: Açúcares, doces e produtos de confeitaria | B41: =COUNTIF(Alimentos!$A$2:$A$255,$A41) | C41: =COUNTIFS(Alimentos!$A$2:$A$255,$A41,Alimentos!$E$2:$E$255,"Já no app") | D41: =COUNTIFS(Alimentos!$A$2:$A$255,$A41,Alimentos!$E$2:$E$255,"Falta subir") | E41: =SUMIF(Alimentos!$A$2:$A$255,$A41,Alimentos!$D$2:$D$255)
A42: Farinhas, féculas e massas | B42: =COUNTIF(Alimentos!$A$2:$A$255,$A42) | C42: =COUNTIFS(Alimentos!$A$2:$A$255,$A42,Alimentos!$E$2:$E$255,"Já no app") | D42: =COUNTIFS(Alimentos!$A$2:$A$255,$A42,Alimentos!$E$2:$E$255,"Falta subir") | E42: =SUMIF(Alimentos!$A$2:$A$255,$A42,Alimentos!$D$2:$D$255)
A43: Óleos e gorduras | B43: =COUNTIF(Alimentos!$A$2:$A$255,$A43) | C43: =COUNTIFS(Alimentos!$A$2:$A$255,$A43,Alimentos!$E$2:$E$255,"Já no app") | D43: =COUNTIFS(Alimentos!$A$2:$A$255,$A43,Alimentos!$E$2:$E$255,"Falta subir") | E43: =SUMIF(Alimentos!$A$2:$A$255,$A43,Alimentos!$D$2:$D$255)
A44: Sais e condimentos | B44: =COUNTIF(Alimentos!$A$2:$A$255,$A44) | C44: =COUNTIFS(Alimentos!$A$2:$A$255,$A44,Alimentos!$E$2:$E$255,"Já no app") | D44: =COUNTIFS(Alimentos!$A$2:$A$255,$A44,Alimentos!$E$2:$E$255,"Falta subir") | E44: =SUMIF(Alimentos!$A$2:$A$255,$A44,Alimentos!$D$2:$D$255)
... A48: Vísceras | B48: =COUNTIF(Alimentos!$A$2:$A$255,$A48) | C48: =COUNTIFS(Alimentos!$A$2:$A$255,$A48,Alimentos!$E$2:$E$255,"Já no app") | D48: =COUNTIFS(Alimentos!$A$2:$A$255,$A48,Alimentos!$E$2:$E$255,"Falta subir") | E48: =SUMIF(Alimentos!$A$2:$A$255,$A48,Alimentos!$D$2:$D$255)

Sheet Alimentos
A1: Grupo (POF) | B1: # | C1: Produto (POF/IBGE) | D1: kg/pessoa/ano | E1: Status | F1: Nome no app | G1: kcal | H1: Proteína (g) | I1: Carboidrato (g) | J1: Gordura (g) | K1: Fibra (g) | L1: Sódio (mg) | M1: Fonte do valor | N1: Observação
A2: Bebidas e infusões | B2: 1 | C2: Água mineral | D2: 25.851 | E2: Falta subir | G2: 0 | H2: 0 | I2: 0 | J2: 0 | K2: 0 | L2: 1 | M2: Água — sem valor energético
A3: Bebidas e infusões | B3: 2 | C3: Refrigerante de cola | D3: 6.764 | E3: Já no app | F3: Refrigerante, tipo cola | G3: 33.51 | H3: 0 | I3: 8.66 | J3: 0 | L3: 7.12 | M3: TACO (já no app)
A4: Bebidas e infusões | B4: 3 | C4: Cerveja | D4: 5.907 | E4: Já no app | F4: Cerveja, pilsen 2 | G4: 40.72 | H4: 0.56 | I4: 3.32 | J4: 0 | L4: 4.23 | M4: TACO (já no app)
A5: Bebidas e infusões | B5: 4 | C5: Refrigerante de guaraná | D5: 3.577 | E5: Já no app | F5: Refrigerante, tipo guaraná | G5: 38.7 | H5: 0 | I5: 10 | J5: 0 | L5: 9.01 | M5: TACO (já no app)
A6: Bebidas e infusões | B6: 5 | C6: Café moído | D6: 2.384 | E6: Já no app | F6: Café, infusão 10% | G6: 9.07 | H6: 0.71 | I6: 1.48 | J6: 0.07 | L6: 1.03 | M6: TACO (já no app)
A7: Bebidas e infusões | B7: 6 | C7: Suco de fruta envasado | D7: 2.05 | E7: Já no app | F7: Suco de uva, néctar, caixinha | G7: 41 | H7: 0 | I7: 10 | J7: 0 | K7: 0.1 | L7: 8 | M7: adicionado ao app
A8: Bebidas e infusões | B8: 7 | C8: Refrigerante de laranja | D8: 0.974 | E8: Já no app | F8: Refrigerante, tipo laranja | G8: 45.63 | H8: 0 | I8: 11.79 | J8: 0 | L8: 9.27 | M8: TACO (já no app)
A9: Bebidas e infusões | B9: 8 | C9: Refrigerante de limão | D9: 0.521 | E9: Já no app | F9: Refrigerante, tipo limão | G9: 39.72 | H9: 0 | I9: 10.26 | J9: 0 | L9: 8.8 | M9: TACO (já no app)
A10: Bebidas e infusões | B10: 9 | C10: Vinho | D10: 0.476 | E10: Já no app | F10: Vinho, tinto, de mesa | G10: 85 | H10: 0.07 | I10: 2.61 | J10: 0 | K10: 0 | L10: 4 | M10: adicionado ao app
A11: Bebidas e infusões | B11: 10 | C11: Chá-mate | D11: 0.411 | E11: Já no app | F11: Chá, mate, infusão 5% | G11: 2.73 | H11: 0 | I11: 0.64 | J11: 0.05 | L11: 0 | M11: TACO (já no app)
A12: Bebidas e infusões | B12: 11 | C12: Suco de fruta em pó | D12: 0.264 | E12: Já no app | F12: Suco de uva, néctar, caixinha | G12: 41 | H12: 0 | I12: 10 | J12: 0 | K12: 0.1 | L12: 8 | M12: adicionado ao app
A13: Bebidas e infusões | B13: 12 | C13: Refrigerante de uva | D13: 0.206 | E13: Já no app | F13: Refrigerante, tipo água tônica | G13: 30.78 | H13: 0 | I13: 7.95 | J13: 0 | L13: 8.29 | M13: TACO (já no app)
A14: Bebidas e infusões | B14: 13 | C14: Bebida energética | D14: 0.156 | E14: Já no app | F14: Bebida láctea, pêssego | G14: 55.16 | H14: 2.13 | I14: 7.57 | J14: 1.91 | K14: 0.29 | L14: 46.26 | M14: TACO (já no app)
A15: Bebidas e infusões | B15: 14 | C15: Aguardente de cana | D15: 0.146 | E15: Já no app | F15: Cana, aguardente 1 | G15: 215.66 | L15: 3.15 | M15: TACO (já no app)
A16: Bebidas e infusões | B16: 15 | C16: Café solúvel | D16: 0.078 | E16: Já no app | F16: Café, infusão 10% | G16: 9.07 | H16: 0.71 | I16: 1.48 | J16: 0.07 | L16: 1.03 | M16: TACO (já no app)
A17: Bebidas e infusões | B17: 16 | C17: Refrigerante de maçã | D17: 0.013 | E17: Já no app | F17: Refrigerante, tipo água tônica | G17: 30.78 | H17: 0 | I17: 7.95 | J17: 0 | L17: 8.29 | M17: TACO (já no app)
A18: Laticínios | B18: 1 | C18: Leite de vaca pasteurizado | D18: 20.112 | E18: Já no app | F18: Leite, condensado | G18: 312.57 | H18: 7.67 | I18: 57 | J18: 6.74 | L18: 93.8 | M18: TACO (já no app)
A19: Laticínios | B19: 2 | C19: Leite de vaca fresco | D19: 3.838 | E19: Já no app | F19: Leite, condensado | G19: 312.57 | H19: 7.67 | I19: 57 | J19: 6.74 | L19: 93.8 | M19: TACO (já no app)
A20: Laticínios | B20: 3 | C20: Iogurte | D20: 1.554 | E20: Já no app | F20: Iogurte, natural | G20: 51.49 | H20: 4.06 | I20: 1.92 | J20: 3.04 | L20: 51.62 | M20: TACO (já no app)
A21: Laticínios | B21: 4 | C21: Leite em pó integral | D21: 0.947 | E21: Já no app | F21: Leite, de vaca, integral | G21: 64 | H21: 2.9 | I21: 5.9 | J21: 3.2 | L21: 63.76 | M21: TACO (já no app)
A22: Laticínios | B22: 5 | C22: Leite fermentado | D22: 0.946 | E22: Já no app | F22: Leite, fermentado | G22: 69.62 | H22: 1.89 | I22: 15.67 | J22: 0.1 | L22: 33.43 | M22: TACO (já no app)
A23: Laticínios | B23: 6 | C23: Queijo mozarela | D23: 0.809 | E23: Já no app | F23: Queijo, mozarela | G23: 329.87 | H23: 22.65 | I23: 3.05 | J23: 25.18 | L23: 581.36 | M23: TACO (já no app)
A24: Laticínios | B24: 7 | C24: Leite condensado | D24: 0.737 | E24: Já no app | F24: Leite, condensado | G24: 312.57 | H24: 7.67 | I24: 57 | J24: 6.74 | L24: 93.8 | M24: TACO (já no app)
A25: Laticínios | B25: 8 | C25: Queijo minas | D25: 0.565 | E25: Já no app | F25: Queijo, minas, frescal | G25: 264.27 | H25: 17.41 | I25: 3.24 | J25: 20.18 | L25: 31.23 | M25: TACO (já no app)
A26: Laticínios | B26: 9 | C26: Creme de leite | D26: 0.469 | E26: Já no app | F26: Creme de Leite | G26: 221.48 | H26: 1.51 | I26: 4.51 | J26: 22.48 | L26: 51.72 | M26: TACO (já no app)
A27: Laticínios | B27: 10 | C27: Manteiga | D27: 0.351 | E27: Já no app | F27: Couve, manteiga, crua | G27: 27.06 | H27: 2.87 | I27: 4.33 | J27: 0.55 | K27: 3.12 | L27: 6.17 | M27: TACO (já no app)
A28: Laticínios | B28: 11 | C28: Requeijão | D28: 0.285 | E28: Já no app | F28: Requeijão, light, Tirol | G28: 177 | H28: 11 | I28: 3.3 | J28: 13.3 | K28: 0 | L28: 560 | M28: adicionado ao app
A29: Laticínios | B29: 12 | C29: Queijo prato | D29: 0.267 | E29: Já no app | F29: Queijo, prato | G29: 359.88 | H29: 22.66 | I29: 1.88 | J29: 29.11 | L29: 579.77 | M29: TACO (já no app)
A30: Laticínios | B30: 13 | C30: Queijo parmezão | D30: 0.074 | E30: Já no app | F30: Queijo, minas, frescal | G30: 264.27 | H30: 17.41 | I30: 3.24 | J30: 20.18 | L30: 31.23 | M30: TACO (já no app)
A31: Laticínios | B31: 14 | C31: Leite em pó desengordurado | D31: 0.058 | E31: Já no app | F31: Leite, condensado | G31: 312.57 | H31: 7.67 | I31: 57 | J31: 6.74 | L31: 93.8 | M31: TACO (já no app)
A32: Cereais e leguminosas | B32: 1 | C32: Arroz polido | D32: 18.224 | E32: Já no app | F32: Arroz, integral, cozido | G32: 123.53 | H32: 2.59 | I32: 25.81 | J32: 1 | K32: 2.75 | L32: 1.24 | M32: TACO (já no app)
A33: Cereais e leguminosas | B33: 2 | C33: Feijão-rajado | D33: 2.615 | E33: Já no app | F33: Feijão, rajado, cozido | G33: 84.7 | H33: 5.54 | I33: 15.27 | J33: 0.4 | K33: 9.32 | L33: 0.69 | M33: TACO (já no app)
A34: Cereais e leguminosas | B34: 3 | C34: Feijão-preto | D34: 1.297 | E34: Já no app | F34: Feijão, preto, cozido | G34: 77.03 | H34: 4.48 | I34: 14.01 | J34: 0.54 | K34: 8.4 | L34: 1.85 | M34: TACO (já no app)
A35: Cereais e leguminosas | B35: 4 | C35: Milho em grão | D35: 0.733 | E35: Já no app | F35: Milho, amido, cru | G35: 361.37 | H35: 0.6 | I35: 87.15 | J35: 0 | K35: 0.74 | L35: 8.08 | M35: TACO (já no app)
A36: Cereais e leguminosas | B36: 5 | C36: Feijão-mulatinho | D36: 0.692 | E36: Já no app | F36: Feijão, broto, cru | G36: 38.72 | H36: 4.17 | I36: 7.76 | J36: 0.1 | K36: 1.97 | L36: 1.79 | M36: TACO (já no app)
A37: Cereais e leguminosas | B37: 6 | C37: Feijão-fradinho | D37: 0.495 | E37: Já no app | F37: Feijão, fradinho, cozido | G37: 78.01 | H37: 5.09 | I37: 13.5 | J37: 0.64 | K37: 7.47 | L37: 0.98 | M37: TACO (já no app)
A38: Cereais e leguminosas | B38: 7 | C38: Milho verde em espiga | D38: 0.306 | E38: Já no app | F38: Milho, verde, cru | G38: 138.17 | H38: 6.59 | I38: 28.56 | J38: 0.61 | K38: 3.92 | L38: 1.12 | M38: TACO (já no app)
A39: Cereais e leguminosas | B39: 8 | C39: Milho verde em conserva | D39: 0.212 | E39: Já no app | F39: Milho, verde, cru | G39: 138.17 | H39: 6.59 | I39: 28.56 | J39: 0.61 | K39: 3.92 | L39: 1.12 | M39: TACO (já no app)
A40: Cereais e leguminosas | B40: 9 | C40: Feijão-jalo | D40: 0.08 | E40: Já no app | F40: Feijão, jalo, cozido | G40: 92.74 | H40: 6.14 | I40: 16.5 | J40: 0.51 | K40: 13.87 | L40: 0.52 | M40: TACO (já no app)
...

Sheet Para subir
A1: Alimentos que faltam no app, com valor nutricional já pesquisado
A2: Estes são os únicos itens da POF sem equivalente na base. Confira e me diga quais aprova que eu subo.
A4: Grupo (POF) | B4: Produto | C4: kg/pessoa/ano | D4: kcal | E4: Proteína (g) | F4: Carboidrato (g) | G4: Gordura (g) | H4: Fibra (g) | I4: Sódio (mg) | J4: Fonte do valor | K4: Aprovar? (S/N)
A5: Bebidas e infusões | B5: Água mineral | C5: 25.851 | D5: 0 | E5: 0 | F5: 0 | G5: 0 | H5: 0 | I5: 1 | J5: Água — sem valor energético
A6: Panificados | B6: Rosca doce | C6: 0.195 | D6: 372 | E6: 6.2 | F6: 50.9 | G6: 16.4 | H6: 2.4 | I6: 304 | J6: USDA (sweet rolls, cinnamon)
A7: Aves e ovos | B7: Miúdos de frango | C7: 0.166 | D7: 124 | E7: 17.9 | F7: 1.8 | G7: 4.47 | H7: 0 | I7: 77 | J7: USDA (chicken giblets, raw)
A8: Aves e ovos | B8: Pato inteiro ou em cortes | C8: 0.019 | D8: 130 | E8: 18.3 | F8: 0.89 | G8: 5.95 | H8: 0 | I8: 74 | J8: TBCA (pato s/ pele, cru)
A9: Carnes | B9: Paio | C9: 0.009 | D9: 309 | E9: 12 | F9: 0.94 | G9: 28.2 | H9: 0 | I9: 827 | J9: USDA (smoked link sausage, pork) — aproximação
A10: Açúcares, doces e produtos de confeitaria | B10: Sorvete | C10: 0.882 | D10: 210 | E10: 3.5 | F10: 26.6 | G10: 10.1 | H10: 0.93 | I10: 60 | J10: TBCA (conferido: USDA 207/3,5/23,6/11)
A11: Açúcares, doces e produtos de confeitaria | B11: Bombom | C11: 0.153 | D11: 548 | E11: 6.15 | F11: 60.9 | G11: 31.5 | H11: 1.92 | I11: 77.5 | J11: TBCA (bombom chocolate ao leite)
A12: Óleos e gorduras | B12: Banha de porco | C12: 0.082 | D12: 900 | E12: 0 | F12: 0 | G12: 100 | H12: 0 | I12: 0 | J12: TBCA (conferido: USDA 902/100)
A13: Sais e condimentos | B13: Colorau | C13: 0.065 | D13: 318 | E13: 8.67 | F13: 73 | G13: 6.14 | H13: 32.1 | I13: 12.3 | J13: TBCA (colorífico/urucum em pó)
A14: Pescados | B14: Tambaqui fresco | C14: 0.18 | D14: 140 | E14: 19.9 | F14: 0 | G14: 6.67 | H14: 0 | I14: 56.7 | J14: TBCA (tambaqui cru)
A15: Pescados | B15: Curimatã fresco | C15: 0.048 | D15: 148 | E15: 18 | F15: 0 | G15: 8.42 | H15: 0 | I15: 47 | J15: TBCA (corimba/curimatã, filé cru)
A16: Pescados | B16: Tainha fresca | C16: 0.042 | D16: 150 | E16: 25.2 | F16: 0 | G16: 5.5 | H16: 0 | I16: 48.6 | J16: TBCA (tainha, filé cru)
... A18: Pescados | B18: Anchova fresca | C18: 0.012 | D18: 179 | E18: 16.8 | F18: 0 | G18: 12.4 | H18: 0 | I18: 119 | J18: TBCA (anchova, filé fresco)
A20: Amarelo = célula pra você preencher
A21: Não entram aqui 9 itens sem fonte confiável de composição (ver aba Alimentos, linhas em cinza): peixes regionais amazônicos e 'massa de pizza'. Prefiro não cadastrar valor que eu não consiga confirmar.
